Error:

ValueError: 'far_980_a_935093c683edbf2087946594df4e196c.png' is not in list

Names of files in the csv do not match up with the npy
